[backend/att]: An exception occurred
Traceback (most recent call last):
  File "/usr/local/lib/python2.7/dist-packages/RapidSMS-0.9.6a-py2.7.egg/rapidsms/router.py", line 127, in _start_backend
    started = backend.start()
  File "/usr/local/lib/python2.7/dist-packages/RapidSMS-0.9.6a-py2.7.egg/rapidsms/backends/gsm.py", line 159, in start
    self.modem = pygsm.GsmModem(logger=self.gsm_log, **self.modem_kwargs)
  File "/usr/local/lib/python2.7/dist-packages/pygsm/gsmmodem.py", line 126, in __init__
    self.boot()
  File "/usr/local/lib/python2.7/dist-packages/pygsm/gsmmodem.py", line 243, in boot
    self.set_modem_config()
  File "/usr/local/lib/python2.7/dist-packages/pygsm/gsmmodem.py", line 220, in set_modem_config
    self.command(self.smshandler.get_mode_cmd()      ) # make sure in PDU mode
  File "/usr/local/lib/python2.7/dist-packages/pygsm/gsmmodem.py", line 375, in command
    raise(err)
GsmReadTimeoutError
[router]: waiting 15 seconds before retrying
[router]: starting backend
[backend/att]: Connecting and booting via pyGSM...
[backend/att]: debug: Booting
[backend/att]: debug: Connecting
[backend/att]: write: 'ATE0\r'
[backend/att]: write: 'AT+CMEE=1\r'
[backend/att]: write: 'AT+WIND=0\r'
[backend/att]: write: 'AT+CSMS=1\r'
[router]: caught exception in backend pyGSM: device reports readiness to read but returned no data (device disconnected?)
[backend/att]: An exception occurred
Traceback (most recent call last):
  File "/usr/local/lib/python2.7/dist-packages/RapidSMS-0.9.6a-py2.7.egg/rapidsms/router.py", line 127, in _start_backend
    started = backend.start()
  File "/usr/local/lib/python2.7/dist-packages/RapidSMS-0.9.6a-py2.7.egg/rapidsms/backends/gsm.py", line 159, in start
    self.modem = pygsm.GsmModem(logger=self.gsm_log, **self.modem_kwargs)
  File "/usr/local/lib/python2.7/dist-packages/pygsm/gsmmodem.py", line 126, in __init__
    self.boot()
  File "/usr/local/lib/python2.7/dist-packages/pygsm/gsmmodem.py", line 243, in boot
    self.set_modem_config()
  File "/usr/local/lib/python2.7/dist-packages/pygsm/gsmmodem.py", line 219, in set_modem_config
    self.command("AT+CSMS=1", raise_errors=False) # set SMS mode to phase 2+
  File "/usr/local/lib/python2.7/dist-packages/pygsm/gsmmodem.py", line 349, in command
    read_timeout=read_timeout)
  File "/usr/local/lib/python2.7/dist-packages/pygsm/devicewrapper.py", line 102, in read_lines
    read_timeout=read_timeout)
  File "/usr/local/lib/python2.7/dist-packages/pygsm/devicewrapper.py", line 71, in _read
    buf = self.device.read()
  File "/usr/lib/python2.7/dist-packages/serial/serialposix.py", line 456, in read
    raise SerialException('device reports readiness to read but returned no data (device disconnected?)')
SerialException: device reports readiness to read but returned no data (device disconnected?)
[router]: waiting 15 seconds before retrying
[router]: starting backend
[backend/att]: Connecting and booting via pyGSM...
[backend/att]: debug: Booting
[backend/att]: debug: Connecting
[router]: caught exception in backend pyGSM: could not open port /dev/ttyUSB0: [Errno 2] No such file or directory: '/dev/ttyUSB0'
[backend/att]: An exception occurred
Traceback (most recent call last):
  File "/usr/local/lib/python2.7/dist-packages/RapidSMS-0.9.6a-py2.7.egg/rapidsms/router.py", line 127, in _start_backend
    started = backend.start()
  File "/usr/local/lib/python2.7/dist-packages/RapidSMS-0.9.6a-py2.7.egg/rapidsms/backends/gsm.py", line 159, in start
    self.modem = pygsm.GsmModem(logger=self.gsm_log, **self.modem_kwargs)
  File "/usr/local/lib/python2.7/dist-packages/pygsm/gsmmodem.py", line 126, in __init__
    self.boot()
  File "/usr/local/lib/python2.7/dist-packages/pygsm/gsmmodem.py", line 240, in boot
    self.connect()
  File "/usr/local/lib/python2.7/dist-packages/pygsm/gsmmodem.py", line 176, in connect
    **self.device_kwargs)
  File "/usr/local/lib/python2.7/dist-packages/pygsm/devicewrapper.py", line 33, in __init__
    self.device = serial.Serial(*args, **kwargs)
  File "/usr/lib/python2.7/dist-packages/serial/serialutil.py", line 260, in __init__
    self.open()
  File "/usr/lib/python2.7/dist-packages/serial/serialposix.py", line 276, in open
    raise SerialException("could not open port %s: %s" % (self._port, msg))
SerialException: could not open port /dev/ttyUSB0: [Errno 2] No such file or directory: '/dev/ttyUSB0'
[router]: waiting 15 seconds before retrying
[router]: starting backend
[backend/att]: Connecting and booting via pyGSM...
[backend/att]: debug: Booting
[backend/att]: debug: Connecting
[router]: caught exception in backend pyGSM: could not open port /dev/ttyUSB0: [Errno 2] No such file or directory: '/dev/ttyUSB0'
[backend/att]: An exception occurred
Traceback (most recent call last):
  File "/usr/local/lib/python2.7/dist-packages/RapidSMS-0.9.6a-py2.7.egg/rapidsms/router.py", line 127, in _start_backend
    started = backend.start()
  File "/usr/local/lib/python2.7/dist-packages/RapidSMS-0.9.6a-py2.7.egg/rapidsms/backends/gsm.py", line 159, in start
    self.modem = pygsm.GsmModem(logger=self.gsm_log, **self.modem_kwargs)
  File "/usr/local/lib/python2.7/dist-packages/pygsm/gsmmodem.py", line 126, in __init__
    self.boot()
  File "/usr/local/lib/python2.7/dist-packages/pygsm/gsmmodem.py", line 240, in boot
    self.connect()
  File "/usr/local/lib/python2.7/dist-packages/pygsm/gsmmodem.py", line 176, in connect
    **self.device_kwargs)
  File "/usr/local/lib/python2.7/dist-packages/pygsm/devicewrapper.py", line 33, in __init__
    self.device = serial.Serial(*args, **kwargs)
  File "/usr/lib/python2.7/dist-packages/serial/serialutil.py", line 260, in __init__
    self.open()
  File "/usr/lib/python2.7/dist-packages/serial/serialposix.py", line 276, in open
    raise SerialException("could not open port %s: %s" % (self._port, msg))
SerialException: could not open port /dev/ttyUSB0: [Errno 2] No such file or directory: '/dev/ttyUSB0'
[router]: waiting 15 seconds before retrying
[router]: starting backend
[backend/att]: Connecting and booting via pyGSM...
[backend/att]: debug: Booting
[backend/att]: debug: Connecting
[router]: caught exception in backend pyGSM: could not open port /dev/ttyUSB0: [Errno 2] No such file or directory: '/dev/ttyUSB0'
[backend/att]: An exception occurred
Traceback (most recent call last):
  File "/usr/local/lib/python2.7/dist-packages/RapidSMS-0.9.6a-py2.7.egg/rapidsms/router.py", line 127, in _start_backend
    started = backend.start()
  File "/usr/local/lib/python2.7/dist-packages/RapidSMS-0.9.6a-py2.7.egg/rapidsms/backends/gsm.py", line 159, in start
    self.modem = pygsm.GsmModem(logger=self.gsm_log, **self.modem_kwargs)
  File "/usr/local/lib/python2.7/dist-packages/pygsm/gsmmodem.py", line 126, in __init__
    self.boot()
  File "/usr/local/lib/python2.7/dist-packages/pygsm/gsmmodem.py", line 240, in boot
    self.connect()
  File "/usr/local/lib/python2.7/dist-packages/pygsm/gsmmodem.py", line 176, in connect
    **self.device_kwargs)
  File "/usr/local/lib/python2.7/dist-packages/pygsm/devicewrapper.py", line 33, in __init__
    self.device = serial.Serial(*args, **kwargs)
  File "/usr/lib/python2.7/dist-packages/serial/serialutil.py", line 260, in __init__
    self.open()
  File "/usr/lib/python2.7/dist-packages/serial/serialposix.py", line 276, in open
    raise SerialException("could not open port %s: %s" % (self._port, msg))
SerialException: could not open port /dev/ttyUSB0: [Errno 2] No such file or directory: '/dev/ttyUSB0'
[router]: waiting 15 seconds before retrying
[router]: starting backend
[backend/att]: Connecting and booting via pyGSM...
[backend/att]: debug: Booting
[backend/att]: debug: Connecting
[router]: caught exception in backend pyGSM: could not open port /dev/ttyUSB0: [Errno 2] No such file or directory: '/dev/ttyUSB0'
