[backend/att]: Connecting and booting via pyGSM...
[backend/att]: debug: Booting
[backend/att]: debug: Connecting
[backend/att]: write: 'ATE0\r'
[backend/att]: write: 'AT+CMEE=1\r'
[backend/att]: write: 'AT+WIND=0\r'
[backend/att]: write: 'AT+CSMS=1\r'
[backend/att]: write: 'AT+CMGF=0\r'
[router]: caught exception in backend pyGSM: 
[backend/att]: An exception occurred
Traceback (most recent call last):
  File "/usr/local/lib/python2.7/dist-packages/RapidSMS-0.9.6a-py2.7.egg/rapidsms/router.py", line 127, in _start_backend
    started = backend.start()
  File "/usr/local/lib/python2.7/dist-packages/RapidSMS-0.9.6a-py2.7.egg/rapidsms/backends/gsm.py", line 159, in start
    self.modem = pygsm.GsmModem(logger=self.gsm_log, **self.modem_kwargs)
  File "/usr/local/lib/python2.7/dist-packages/pygsm/gsmmodem.py", line 126, in __init__
    self.boot()
  File "/usr/local/lib/python2.7/dist-packages/pygsm/gsmmodem.py", line 243, in boot
    self.set_modem_config()
  File "/usr/local/lib/python2.7/dist-packages/pygsm/gsmmodem.py", line 220, in set_modem_config
    self.command(self.smshandler.get_mode_cmd()      ) # make sure in PDU mode
  File "/usr/local/lib/python2.7/dist-packages/pygsm/gsmmodem.py", line 375, in command
    raise(err)
GsmReadTimeoutError
[router]: waiting 15 seconds before retrying
[router]: starting backend
[backend/att]: Connecting and booting via pyGSM...
[backend/att]: debug: Booting
[backend/att]: debug: Connecting
[backend/att]: write: 'ATE0\r'
[backend/att]: write: 'AT+CMEE=1\r'
[backend/att]: write: 'AT+WIND=0\r'
[backend/att]: write: 'AT+CSMS=1\r'
[backend/att]: write: 'AT+CMGF=0\r'
[router]: caught exception in backend pyGSM: 
[backend/att]: An exception occurred
Traceback (most recent call last):
  File "/usr/local/lib/python2.7/dist-packages/RapidSMS-0.9.6a-py2.7.egg/rapidsms/router.py", line 127, in _start_backend
    started = backend.start()
  File "/usr/local/lib/python2.7/dist-packages/RapidSMS-0.9.6a-py2.7.egg/rapidsms/backends/gsm.py", line 159, in start
    self.modem = pygsm.GsmModem(logger=self.gsm_log, **self.modem_kwargs)
  File "/usr/local/lib/python2.7/dist-packages/pygsm/gsmmodem.py", line 126, in __init__
    self.boot()
  File "/usr/local/lib/python2.7/dist-packages/pygsm/gsmmodem.py", line 243, in boot
    self.set_modem_config()
  File "/usr/local/lib/python2.7/dist-packages/pygsm/gsmmodem.py", line 220, in set_modem_config
    self.command(self.smshandler.get_mode_cmd()      ) # make sure in PDU mode
  File "/usr/local/lib/python2.7/dist-packages/pygsm/gsmmodem.py", line 375, in command
    raise(err)
GsmReadTimeoutError
[router]: waiting 15 seconds before retrying
[router]: starting backend
[backend/att]: Connecting and booting via pyGSM...
[backend/att]: debug: Booting
[backend/att]: debug: Connecting
[backend/att]: write: 'ATE0\r'
[backend/att]: write: 'AT+CMEE=1\r'
[backend/att]: write: 'AT+WIND=0\r'
[backend/att]: write: 'AT+CSMS=1\r'
[backend/att]: write: 'AT+CMGF=0\r'
[router]: caught exception in backend pyGSM: 
[backend/att]: An exception occurred
Traceback (most recent call last):
  File "/usr/local/lib/python2.7/dist-packages/RapidSMS-0.9.6a-py2.7.egg/rapidsms/router.py", line 127, in _start_backend
    started = backend.start()
  File "/usr/local/lib/python2.7/dist-packages/RapidSMS-0.9.6a-py2.7.egg/rapidsms/backends/gsm.py", line 159, in start
    self.modem = pygsm.GsmModem(logger=self.gsm_log, **self.modem_kwargs)
  File "/usr/local/lib/python2.7/dist-packages/pygsm/gsmmodem.py", line 126, in __init__
    self.boot()
  File "/usr/local/lib/python2.7/dist-packages/pygsm/gsmmodem.py", line 243, in boot
    self.set_modem_config()
  File "/usr/local/lib/python2.7/dist-packages/pygsm/gsmmodem.py", line 220, in set_modem_config
    self.command(self.smshandler.get_mode_cmd()      ) # make sure in PDU mode
  File "/usr/local/lib/python2.7/dist-packages/pygsm/gsmmodem.py", line 375, in command
    raise(err)
GsmReadTimeoutError
[router]: waiting 15 seconds before retrying
[router]: starting backend
[backend/att]: Connecting and booting via pyGSM...
[backend/att]: debug: Booting
[backend/att]: debug: Connecting
[backend/att]: write: 'ATE0\r'
[backend/att]: write: 'AT+CMEE=1\r'
[backend/att]: write: 'AT+WIND=0\r'
[backend/att]: write: 'AT+CSMS=1\r'
[backend/att]: write: 'AT+CMGF=0\r'
[router]: caught exception in backend pyGSM: 
[backend/att]: An exception occurred
Traceback (most recent call last):
  File "/usr/local/lib/python2.7/dist-packages/RapidSMS-0.9.6a-py2.7.egg/rapidsms/router.py", line 127, in _start_backend
    started = backend.start()
  File "/usr/local/lib/python2.7/dist-packages/RapidSMS-0.9.6a-py2.7.egg/rapidsms/backends/gsm.py", line 159, in start
    self.modem = pygsm.GsmModem(logger=self.gsm_log, **self.modem_kwargs)
  File "/usr/local/lib/python2.7/dist-packages/pygsm/gsmmodem.py", line 126, in __init__
    self.boot()
  File "/usr/local/lib/python2.7/dist-packages/pygsm/gsmmodem.py", line 243, in boot
    self.set_modem_config()
  File "/usr/local/lib/python2.7/dist-packages/pygsm/gsmmodem.py", line 220, in set_modem_config
    self.command(self.smshandler.get_mode_cmd()      ) # make sure in PDU mode
  File "/usr/local/lib/python2.7/dist-packages/pygsm/gsmmodem.py", line 375, in command
    raise(err)
GsmReadTimeoutError
[router]: waiting 15 seconds before retrying
[router]: starting backend
[backend/att]: Connecting and booting via pyGSM...
[backend/att]: debug: Booting
[backend/att]: debug: Connecting
[backend/att]: write: 'ATE0\r'
[backend/att]: write: 'AT+CMEE=1\r'
[backend/att]: write: 'AT+WIND=0\r'
[backend/att]: write: 'AT+CSMS=1\r'
[backend/att]: write: 'AT+CMGF=0\r'
[router]: caught exception in backend pyGSM: 
[backend/att]: An exception occurred
Traceback (most recent call last):
  File "/usr/local/lib/python2.7/dist-packages/RapidSMS-0.9.6a-py2.7.egg/rapidsms/router.py", line 127, in _start_backend
    started = backend.start()
  File "/usr/local/lib/python2.7/dist-packages/RapidSMS-0.9.6a-py2.7.egg/rapidsms/backends/gsm.py", line 159, in start
    self.modem = pygsm.GsmModem(logger=self.gsm_log, **self.modem_kwargs)
  File "/usr/local/lib/python2.7/dist-packages/pygsm/gsmmodem.py", line 126, in __init__
    self.boot()
  File "/usr/local/lib/python2.7/dist-packages/pygsm/gsmmodem.py", line 243, in boot
    self.set_modem_config()
  File "/usr/local/lib/python2.7/dist-packages/pygsm/gsmmodem.py", line 220, in set_modem_config
    self.command(self.smshandler.get_mode_cmd()      ) # make sure in PDU mode
  File "/usr/local/lib/python2.7/dist-packages/pygsm/gsmmodem.py", line 375, in command
    raise(err)
GsmReadTimeoutError
[router]: waiting 15 seconds before retrying
[router]: starting backend
[backend/att]: Connecting and booting via pyGSM...
[backend/att]: debug: Booting
[backend/att]: debug: Connecting
[backend/att]: write: 'ATE0\r'
[backend/att]: write: 'AT+CMEE=1\r'
[backend/att]: write: 'AT+WIND=0\r'
[backend/att]: write: 'AT+CSMS=1\r'
[backend/att]: write: 'AT+CMGF=0\r'
[router]: caught exception in backend pyGSM: 
[backend/att]: An exception occurred
Traceback (most recent call last):
  File "/usr/local/lib/python2.7/dist-packages/RapidSMS-0.9.6a-py2.7.egg/rapidsms/router.py", line 127, in _start_backend
    started = backend.start()
  File "/usr/local/lib/python2.7/dist-packages/RapidSMS-0.9.6a-py2.7.egg/rapidsms/backends/gsm.py", line 159, in start
    self.modem = pygsm.GsmModem(logger=self.gsm_log, **self.modem_kwargs)
  File "/usr/local/lib/python2.7/dist-packages/pygsm/gsmmodem.py", line 126, in __init__
    self.boot()
  File "/usr/local/lib/python2.7/dist-packages/pygsm/gsmmodem.py", line 243, in boot
    self.set_modem_config()
  File "/usr/local/lib/python2.7/dist-packages/pygsm/gsmmodem.py", line 220, in set_modem_config
    self.command(self.smshandler.get_mode_cmd()      ) # make sure in PDU mode
  File "/usr/local/lib/python2.7/dist-packages/pygsm/gsmmodem.py", line 375, in command
    raise(err)
GsmReadTimeoutError
[router]: waiting 15 seconds before retrying
[router]: starting backend
[backend/att]: Connecting and booting via pyGSM...
[backend/att]: debug: Booting
[backend/att]: debug: Connecting
[backend/att]: write: 'ATE0\r'
