[backend/att]: An exception occurred
Traceback (most recent call last):
  File "/usr/local/lib/python2.7/dist-packages/RapidSMS-0.9.6a-py2.7.egg/rapidsms/router.py", line 127, in _start_backend
    started = backend.start()
  File "/usr/local/lib/python2.7/dist-packages/RapidSMS-0.9.6a-py2.7.egg/rapidsms/backends/gsm.py", line 159, in start
    self.modem = pygsm.GsmModem(logger=self.gsm_log, **self.modem_kwargs)
  File "/usr/local/lib/python2.7/dist-packages/pygsm/gsmmodem.py", line 126, in __init__
    self.boot()
  File "/usr/local/lib/python2.7/dist-packages/pygsm/gsmmodem.py", line 240, in boot
    self.connect()
  File "/usr/local/lib/python2.7/dist-packages/pygsm/gsmmodem.py", line 176, in connect
    **self.device_kwargs)
  File "/usr/local/lib/python2.7/dist-packages/pygsm/devicewrapper.py", line 33, in __init__
    self.device = serial.Serial(*args, **kwargs)
  File "/usr/lib/python2.7/dist-packages/serial/serialutil.py", line 260, in __init__
    self.open()
  File "/usr/lib/python2.7/dist-packages/serial/serialposix.py", line 276, in open
    raise SerialException("could not open port %s: %s" % (self._port, msg))
SerialException: could not open port /dev/ttyUSB0: [Errno 2] No such file or directory: '/dev/ttyUSB0'
[router]: waiting 15 seconds before retrying
[router]: starting backend
[backend/att]: Connecting and booting via pyGSM...
[backend/att]: debug: Booting
[backend/att]: debug: Connecting
[backend/att]: debug: Disconnecting
[router]: caught exception in backend pyGSM: could not open port /dev/ttyUSB0: [Errno 2] No such file or directory: '/dev/ttyUSB0'
[backend/att]: An exception occurred
Traceback (most recent call last):
  File "/usr/local/lib/python2.7/dist-packages/RapidSMS-0.9.6a-py2.7.egg/rapidsms/router.py", line 127, in _start_backend
    started = backend.start()
  File "/usr/local/lib/python2.7/dist-packages/RapidSMS-0.9.6a-py2.7.egg/rapidsms/backends/gsm.py", line 159, in start
    self.modem = pygsm.GsmModem(logger=self.gsm_log, **self.modem_kwargs)
  File "/usr/local/lib/python2.7/dist-packages/pygsm/gsmmodem.py", line 126, in __init__
    self.boot()
  File "/usr/local/lib/python2.7/dist-packages/pygsm/gsmmodem.py", line 240, in boot
    self.connect()
  File "/usr/local/lib/python2.7/dist-packages/pygsm/gsmmodem.py", line 176, in connect
    **self.device_kwargs)
  File "/usr/local/lib/python2.7/dist-packages/pygsm/devicewrapper.py", line 33, in __init__
    self.device = serial.Serial(*args, **kwargs)
  File "/usr/lib/python2.7/dist-packages/serial/serialutil.py", line 260, in __init__
    self.open()
  File "/usr/lib/python2.7/dist-packages/serial/serialposix.py", line 276, in open
    raise SerialException("could not open port %s: %s" % (self._port, msg))
SerialException: could not open port /dev/ttyUSB0: [Errno 2] No such file or directory: '/dev/ttyUSB0'
[router]: waiting 15 seconds before retrying
[router]: Caught KeyboardInterrupt
[router]: Stopping...
[backend/att]: debug: Disconnecting
[router]: returning from _start_backend
[router]: backend <backend: message_tester> terminated normally
[router]: Stopped
[django.db.backends]: (0.000) SELECT `rapidsms_backend`.`name` FROM `rapidsms_backend`; args=()
[django.db.backends]: (0.000) SELECT `rapidsms_app`.`module` FROM `rapidsms_app`; args=()
[router]: Starting RapidSMS...
[router]: starting backend
[router]: starting backend
[backend/att]: Connecting and booting via pyGSM...
[app/handlers]: Registered: EchoHandler, PingHandler
[backend/att]: debug: Booting
[backend/att]: debug: Connecting
[router]: Started
[backend/att]: write: 'ATE0\r'
[backend/att]: write: 'AT+CMEE=1\r'
[router]: Caught KeyboardInterrupt
[router]: Stopping...
[backend/att]: Worker thread did not terminate
[router]: backend <backend: message_tester> terminated normally
[router]: Stopped
[django.db.backends]: (0.001) SELECT `rapidsms_backend`.`name` FROM `rapidsms_backend`; args=()
[django.db.backends]: (0.000) SELECT `rapidsms_app`.`module` FROM `rapidsms_app`; args=()
[router]: Starting RapidSMS...
[router]: starting backend
[backend/att]: Connecting and booting via pyGSM...
[backend/att]: debug: Booting
[backend/att]: debug: Connecting
[router]: starting backend
[backend/att]: write: 'ATE0\r'
[app/handlers]: Registered: EchoHandler, PingHandler
[router]: Started
[backend/att]: write: 'AT+CMEE=1\r'
[backend/att]: write: 'AT+WIND=0\r'
[backend/att]: write: 'AT+CSMS=1\r'
[backend/att]: write: 'AT+CMGF=0\r'
[router]: caught exception in backend pyGSM: 
[backend/att]: An exception occurred
Traceback (most recent call last):
  File "/usr/local/lib/python2.7/dist-packages/RapidSMS-0.9.6a-py2.7.egg/rapidsms/router.py", line 127, in _start_backend
    started = backend.start()
  File "/usr/local/lib/python2.7/dist-packages/RapidSMS-0.9.6a-py2.7.egg/rapidsms/backends/gsm.py", line 159, in start
    self.modem = pygsm.GsmModem(logger=self.gsm_log, **self.modem_kwargs)
  File "/usr/local/lib/python2.7/dist-packages/pygsm/gsmmodem.py", line 126, in __init__
    self.boot()
  File "/usr/local/lib/python2.7/dist-packages/pygsm/gsmmodem.py", line 243, in boot
    self.set_modem_config()
  File "/usr/local/lib/python2.7/dist-packages/pygsm/gsmmodem.py", line 220, in set_modem_config
    self.command(self.smshandler.get_mode_cmd()      ) # make sure in PDU mode
  File "/usr/local/lib/python2.7/dist-packages/pygsm/gsmmodem.py", line 375, in command
    raise(err)
GsmReadTimeoutError
[router]: waiting 15 seconds before retrying
[router]: starting backend
[backend/att]: Connecting and booting via pyGSM...
[backend/att]: debug: Booting
[backend/att]: debug: Connecting
[backend/att]: write: 'ATE0\r'
[backend/att]: write: 'AT+CMEE=1\r'
[backend/att]: write: 'AT+WIND=0\r'
[backend/att]: write: 'AT+CSMS=1\r'
[backend/att]: write: 'AT+CMGF=0\r'
[router]: caught exception in backend pyGSM: 
[backend/att]: An exception occurred
Traceback (most recent call last):
  File "/usr/local/lib/python2.7/dist-packages/RapidSMS-0.9.6a-py2.7.egg/rapidsms/router.py", line 127, in _start_backend
    started = backend.start()
  File "/usr/local/lib/python2.7/dist-packages/RapidSMS-0.9.6a-py2.7.egg/rapidsms/backends/gsm.py", line 159, in start
    self.modem = pygsm.GsmModem(logger=self.gsm_log, **self.modem_kwargs)
  File "/usr/local/lib/python2.7/dist-packages/pygsm/gsmmodem.py", line 126, in __init__
    self.boot()
  File "/usr/local/lib/python2.7/dist-packages/pygsm/gsmmodem.py", line 243, in boot
    self.set_modem_config()
  File "/usr/local/lib/python2.7/dist-packages/pygsm/gsmmodem.py", line 220, in set_modem_config
    self.command(self.smshandler.get_mode_cmd()      ) # make sure in PDU mode
  File "/usr/local/lib/python2.7/dist-packages/pygsm/gsmmodem.py", line 375, in command
    raise(err)
GsmReadTimeoutError
[router]: waiting 15 seconds before retrying
[router]: starting backend
[backend/att]: Connecting and booting via pyGSM...
[backend/att]: debug: Booting
[backend/att]: debug: Connecting
[backend/att]: write: 'ATE0\r'
[backend/att]: write: 'AT+CMEE=1\r'
[backend/att]: write: 'AT+WIND=0\r'
[backend/att]: write: 'AT+CSMS=1\r'
[backend/att]: write: 'AT+CMGF=0\r'
[router]: caught exception in backend pyGSM: 
[backend/att]: An exception occurred
Traceback (most recent call last):
  File "/usr/local/lib/python2.7/dist-packages/RapidSMS-0.9.6a-py2.7.egg/rapidsms/router.py", line 127, in _start_backend
    started = backend.start()
  File "/usr/local/lib/python2.7/dist-packages/RapidSMS-0.9.6a-py2.7.egg/rapidsms/backends/gsm.py", line 159, in start
    self.modem = pygsm.GsmModem(logger=self.gsm_log, **self.modem_kwargs)
  File "/usr/local/lib/python2.7/dist-packages/pygsm/gsmmodem.py", line 126, in __init__
    self.boot()
  File "/usr/local/lib/python2.7/dist-packages/pygsm/gsmmodem.py", line 243, in boot
    self.set_modem_config()
  File "/usr/local/lib/python2.7/dist-packages/pygsm/gsmmodem.py", line 220, in set_modem_config
    self.command(self.smshandler.get_mode_cmd()      ) # make sure in PDU mode
  File "/usr/local/lib/python2.7/dist-packages/pygsm/gsmmodem.py", line 375, in command
    raise(err)
GsmReadTimeoutError
[router]: waiting 15 seconds before retrying
[router]: starting backend
